<?xml version='1.0' encoding='utf-8'?>
<robot xmlns:xacro="http://www.ros.org/wiki/xacro" name="panda">
  <!-- safety_distance: Minimum safety distance in [m] by which the collision volumes are expanded and which is enforced during robot motions -->
  <!-- arm_id: Namespace of the panda arm. Serves to differentiate between arms in case of multiple instances. -->
  <xacro:macro name="panda_arm" params="arm_id:='panda' description_pkg:='franka_description' connected_to:='' xyz:='0 0 0' rpy:='0 0 0' safety_distance:=0">
    <xacro:unless value="${not connected_to}">
      <joint name="${arm_id}_joint_${connected_to}" type="fixed">
        <parent link="${connected_to}"/>
        <child link="${arm_id}_base0"/>
        <origin rpy="${rpy}" xyz="${xyz}"/>
      </joint>
    </xacro:unless>

    <link name="${arm_id}_base0">
    </link>
    <link name="${arm_id}_base1">
    </link>
    <link name="${arm_id}_base_arm">
      <visual>
        <origin xyz="0 0 0" rpy="0 0 0"/>
        <geometry>
          <mesh filename="package://${description_pkg}/meshes/visual/omron.dae"/>
        </geometry>
      </visual>
      <collision>
        <origin xyz="0 0 0.19" rpy="0 0 0"/>
        <geometry>
          <box size="0.68 0.47 0.38" />
        </geometry>
      </collision>
    </link>
    <joint name="${arm_id}_base_joint1" type="revolute">
      <origin rpy="0 0 0" xyz="0 0 0"/>
      <parent link="${arm_id}_base0"/>
      <child link="${arm_id}_base1"/>
      <axis xyz="0 0 1"/>
      <limit effort="87" lower="-999999" upper="999999" velocity="4.0"/>
    </joint>
    <joint name="${arm_id}_base_joint2" type="prismatic">
      <origin rpy="0 0 0" xyz="0 0 0"/>
      <parent link="${arm_id}_base1"/>
      <child link="${arm_id}_base_arm"/>
      <axis xyz="1 0 0"/>
      <limit effort="87" lower="-999999" upper="999999" velocity="4.0"/>
    </joint>

  </xacro:macro>
</robot>
